checking dir: /pscratch/sd/c/cjacobus/tsit/expts/base/checkpoints/
dir exists: /pscratch/sd/c/cjacobus/tsit/expts/base/checkpoints/
2022-07-19 18:20:48,716 - root - INFO - rank 0, begin data loader init
2022-07-19 18:20:48,717 - root - INFO - rank 0, data loader initialized
Network [TSITGenerator] was created. Total number of parameters: 934.7 million. To see the architecture, do print(network).
Network [MultiscaleDiscriminator] was created. Total number of parameters: 22.1 million. To see the architecture, do print(network).
2022-07-19 18:21:06,296 - root - INFO - Loading checkpoint /pscratch/sd/c/cjacobus/tsit/expts/base/checkpoints/ckpt.tar
2022-07-19 18:21:14,706 - root - INFO - Starting Training Loop...
generator made step 0
discriminator made step 0
generator made step 16
discriminator made step 16
generator made step 32
discriminator made step 32
generator made step 48
discriminator made step 48
Rank 0 made one pass
2022-07-19 18:22:30,252 - root - INFO - Total=75.545040, G=60.461465, D=11.848045, data=0.238347, next=2.997183
2022-07-19 18:22:32,881 - root - INFO - Total=2.628003, G=0.112182, data=0.600802, acc=0.760878, agg=0.081108, next=1.073033
fields = 2
Traceback (most recent call last):
  File "train.py", line 34, in <module>
    trainer.build_and_launch()
  File "/global/u1/c/cjacobus/Nyx-TSIT/trainers/pix2pix_trainer.py", line 189, in build_and_launch
    self.train()
  File "/global/u1/c/cjacobus/Nyx-TSIT/trainers/pix2pix_trainer.py", line 220, in train
    fig = viz_fields(fields)
  File "/global/u1/c/cjacobus/Nyx-TSIT/utils/viz.py", line 13, in viz_fields
    plt.imshow(pred, cmap='Blues', norm=Normalize(0., sc))
  File "/opt/conda/lib/python3.8/site-packages/matplotlib/_api/deprecation.py", line 456, in wrapper
    return func(*args, **kwargs)
  File "/opt/conda/lib/python3.8/site-packages/matplotlib/pyplot.py", line 2640, in imshow
    __ret = gca().imshow(
  File "/opt/conda/lib/python3.8/site-packages/matplotlib/_api/deprecation.py", line 456, in wrapper
    return func(*args, **kwargs)
  File "/opt/conda/lib/python3.8/site-packages/matplotlib/__init__.py", line 1412, in inner
    return func(ax, *map(sanitize_sequence, args), **kwargs)
  File "/opt/conda/lib/python3.8/site-packages/matplotlib/axes/_axes.py", line 5488, in imshow
    im.set_data(X)
  File "/opt/conda/lib/python3.8/site-packages/matplotlib/image.py", line 715, in set_data
    raise TypeError("Invalid shape {} for image data"
TypeError: Invalid shape (128, 128, 128) for image data